Traceback (most recent call last):
  File "/opt/hostedtoolcache/Python/3.9.16/x64/lib/python3.9/site-packages/jupyter_cache/executors/utils.py", line 58, in single_nb_execution
    executenb(
  File "/opt/hostedtoolcache/Python/3.9.16/x64/lib/python3.9/site-packages/nbclient/client.py", line 1204, in execute
    return NotebookClient(nb=nb, resources=resources, km=km, **kwargs).execute()
  File "/opt/hostedtoolcache/Python/3.9.16/x64/lib/python3.9/site-packages/nbclient/util.py", line 84, in wrapped
    return just_run(coro(*args, **kwargs))
  File "/opt/hostedtoolcache/Python/3.9.16/x64/lib/python3.9/site-packages/nbclient/util.py", line 62, in just_run
    return loop.run_until_complete(coro)
  File "/opt/hostedtoolcache/Python/3.9.16/x64/lib/python3.9/asyncio/base_events.py", line 647, in run_until_complete
    return future.result()
  File "/opt/hostedtoolcache/Python/3.9.16/x64/lib/python3.9/site-packages/nbclient/client.py", line 663, in async_execute
    await self.async_execute_cell(
  File "/opt/hostedtoolcache/Python/3.9.16/x64/lib/python3.9/site-packages/nbclient/client.py", line 965, in async_execute_cell
    await self._check_raise_for_error(cell, cell_index, exec_reply)
  File "/opt/hostedtoolcache/Python/3.9.16/x64/lib/python3.9/site-packages/nbclient/client.py", line 862, in _check_raise_for_error
    raise CellExecutionError.from_cell_and_msg(cell, exec_reply_content)
nbclient.exceptions.CellExecutionError: An error occurred while executing the following cell:
------------------
from timeseriesflattener.testing.utils_for_testing import load_long_df_with_multiple_values
from timeseriesflattener.utils import split_df_and_register_to_dict
------------------

[0;31m---------------------------------------------------------------------------[0m
[0;31mModuleNotFoundError[0m                       Traceback (most recent call last)
[0;32m/tmp/ipykernel_1920/235604048.py[0m in [0;36m<cell line: 1>[0;34m()[0m
[0;32m----> 1[0;31m [0;32mfrom[0m [0mtimeseriesflattener[0m[0;34m.[0m[0mtesting[0m[0;34m.[0m[0mutils_for_testing[0m [0;32mimport[0m [0mload_long_df_with_multiple_values[0m[0;34m[0m[0;34m[0m[0m
[0m[1;32m      2[0m [0;32mfrom[0m [0mtimeseriesflattener[0m[0;34m.[0m[0mutils[0m [0;32mimport[0m [0msplit_df_and_register_to_dict[0m[0;34m[0m[0;34m[0m[0m

[0;32m~/work/timeseriesflattener/timeseriesflattener/src/timeseriesflattener/testing/utils_for_testing.py[0m in [0;36m<module>[0;34m[0m
[1;32m      7[0m [0;32mimport[0m [0mnumpy[0m [0;32mas[0m [0mnp[0m[0;34m[0m[0;34m[0m[0m
[1;32m      8[0m [0;32mimport[0m [0mpandas[0m [0;32mas[0m [0mpd[0m[0;34m[0m[0;34m[0m[0m
[0;32m----> 9[0;31m [0;32mimport[0m [0mpytest[0m[0;34m[0m[0;34m[0m[0m
[0m[1;32m     10[0m [0;32mfrom[0m [0mpandas[0m [0;32mimport[0m [0mDataFrame[0m[0;34m[0m[0;34m[0m[0m
[1;32m     11[0m [0;32mfrom[0m [0mpandas[0m[0;34m.[0m[0mtesting[0m [0;32mimport[0m [0massert_series_equal[0m[0;34m[0m[0;34m[0m[0m

[0;31mModuleNotFoundError[0m: No module named 'pytest'
ModuleNotFoundError: No module named 'pytest'

